Workbook

Sheet new_jobs
A1: Unique? | B1: final_job_id | C1: platform | D1: company | E1: slug | F1: job_id | G1: title | H1: location | I1: is_remote | J1: is_hybrid | K1: url | L1: description | M1: New | N1: Rem_Hyb
A2: {=SUM((B2=$B$2:$B$127)*1)} -> 1 | B2: greenhouse|figma|5220003004 | C2: greenhouse | D2: Figma | E2: figma | F2: 5220003004 | G2: Data Engineer | H2: San Francisco, CA • New York, NY • United States | I2: 1 | J2: 0 | K2: https://boards.greenhouse.io/figma/jobs/5220003004?gh_jid=5220003004 | L2: Figma is growing our team of passionate creatives and builders on a mission to make design accessible to all. Figma’s platform helps teams bring ideas to life—whether you're brainstorming, creating a prototype, translating designs into code, or iterating with AI. From idea to product, Figma empowers teams to streamline workflows, move faster, and work together in real time from anywhere in the world. If you're excited to shape the future of design and collaboration, join us! We are looking for an experienced Data Engineer to partner with our Data Science and Data Infrastructure teams to own and scale our data pipelines. You’ll also work closely with stakeholders across business teams including sales, marketing, and finance to ensure that the data they need arrives promptly and reliably. You’ll play an integral role in building the metrics and self-serve reporting capabilities to unlock Figma’s next phase of growth. This is a great role for an individual who is passionate about working with data and data systems, and who love s solving problems. You’ll have a good sense for when it makes sense to build fast, scrappy solution s to unblock a key stakeholder vs. when to push back or bring in an outside service. The ideal candidate will be a great communicator who can help coordinate across multiple internal and external teams and take s pride in building end-to-end projects. This is a full time role that can be held from one of our US hubs or remotely in the United States. What you'll do at Figma : Own, build, and maintai n scalable data pipelines that connect various cloud data sources. Develop a deep understanding of Figma’s core data model s and optimize data pipelines for scale. Partner with the Data Science and Data Infrastructure teams to build new foundational data sets that are trusted, well understood, and enable self-service . Work with a wide range of cross-functional stakeholders to derive requirements and architect shared datasets; ability to document, simplify and explain complex problems to different types of audiences. Establish best practices for the development of specialized data sets for analytics and modeling. We'd love to hear from you if you have: 4 + years in a relevant field. Fluency with both SQL and Python. Familiarity with Snowflake, dbt, Dagster, and ETL/reverse ETL tools. Excellent judgment and creative problem solving skills. A self-starting mindset along with strong communication and collaboration skills. While not required, it’s an added plus if you also have: Knowledge in data modeling methodologies to design and build robust data architectures for insightful analytics. Experience with business systems such as Salesforce , Customer IO, Stripe, NetSuite is a big plus. At Figma, one of our values is Grow as you go. We believe in hiring smart, curious people who are excited to learn and develop their skills. If you’re excited about this role but your past experience doesn’t align perfectly with the points outlined in the job description, we encourage you to apply anyways. You may be just the right candidate for this or other roles. Pay Transparency Disclosure If based in Figma’s San Francisco or New York hub offices, this role has the annual base salary range stated below. Job level and actual compensation will be decided based on factors including, but not limited to, individual qualifications objectively assessed during the interview process (including skills and prior relevant experience, potential impact, and scope of role), market demands, and specific work location. The listed range is a guideline, and the range for this role may be modified. For roles that are available to be filled remotely, the pay range is localized according to employee work location by a factor of between 80% and 100% of range. Please discuss your specific work location with your recruiter for more information. Figma offers equity to employees, as well a competitive package of additional benefits, including health, dental & vision, retirement with company contribution, parental leave & reproductive or family planning support, mental health & wellness benefits, generous PTO, company recharge days, a learning & development stipend, a work from home stipend, and cell phone reimbursement. Figma also offers sales incentive pay for most sales roles and an annual bonus plan for eligible non-sales roles. Figma’s compensation and benefits are subject to change and may be modified in the future. Annual Base Salary Range: $140,000 — $348,000 USD At Figma we celebrate and support our differences. We know employing a team rich in diverse thoughts, experiences, and opinions allows our employees, our product and our community to flourish. Figma is an equal opportunity workplace - we are dedicated to equal employment opportunities regardless of race, color, ancestry, religion, sex, national origin, sexual orientation, age, citizenship, marital status, disability, gender identity/expression, veteran status , or any other characteristic protected by law. We also consider qualified applicants regardless of criminal histories, consistent with legal requirements. We will work to ensure individuals with disabilities are provided reasonable accommodation to apply for a role, participate in the interview process, perform essential job functions, and receive other benefits and privileges of employment. If you require accommodation, please reach out to accommodations-ext@figma.com . These modifications enable an individual with a disability to have an equal opportunity not only to get a job, but successfully perform their job tasks to the same extent as people without disabilities. Examples of accommodations include but are not limited to: Holding interviews in an accessible location Enabling closed captioning on video conferencing Ensuring all written communication be compatible with screen readers Changing the mode or format of interviews To ensure the integrity of our hiring process and facilitate a more personal connection, we require all candidates keep their cameras on during video interviews. Additionally, if hired you will be required to attend in person onboarding. By applying for this job, the candidate acknowledges and agrees that any personal data contained in their application or supporting materials will be processed in accordance with Figma's Candidate Privacy Notice . | M2: 0 | N2: =I2+J2 -> 1 | O2: {=OR(B2=Hist!$A$1:$A$85)} -> TRUE
A3: {=SUM((B3=$B$2:$B$127)*1)} -> 1 | B3: greenhouse|figma|5552580004 | C3: greenhouse | D3: Figma | E3: figma | F3: 5552580004 | G3: Data Scientist | H3: San Francisco, CA • New York, NY • United States | I3: 1 | J3: 0 | K3: https://boards.greenhouse.io/figma/jobs/5552580004?gh_jid=5552580004 | L3: Figma is growing our team of passionate creatives and builders on a mission to make design accessible to all. Figma’s platform helps teams bring ideas to life—whether you're brainstorming, creating a prototype, translating designs into code, or iterating with AI. From idea to product, Figma empowers teams to streamline workflows, move faster, and work together in real time from anywhere in the world. If you're excited to shape the future of design and collaboration, join us! We are looking for an experienced Data Scientist to join our growing data team. At Figma, Data Scientists are deeply embedded within cross-functional teams across the company—from Product to Finance, Marketing, and Platform. We are hiring across a number of roles in these areas. This is ideal for someone excited to own high-impact data projects, partner strategically with stakeholders, and shape the future of our products and business. The ideal candidate will bring strong analytical and technical skills, business intuition, and a collaborative mindset to guide decision-making and unlock growth opportunities. You’ll work on problems ranging from understanding user behavior to optimizing revenue strategies, improving internal tooling, and influencing product direction through experimentation and data modeling. This is a full-time role that can be held from one of our US hubs or remotely in the United States. What you’ll do at Figma: Collaborate across teams to define and measure key metrics, design experiments, and uncover insights that inform strategic decisions Build models and analytical frameworks to support product, marketing, platform, or finance initiatives Develop tools, datasets, and systems that enable others to work with data more efficiently and rigorously Own complex data projects end-to-end—from problem scoping to solution delivery Champion data quality, accessibility, and the democratization of data across the organization Partner with Product, Engineering, Design, Research, Sales, Marketing, or Finance to drive impact We'd love to hear from you if you have: 4+ years of experience in Analytics, Data Science, or a related field Fluency in SQL and proficiency in a scripting language like Python or R Experience with distributed data systems (e.g., Redshift, Snowflake, Presto, Hive, Spark) Strong foundation in statistical methods, experimentation, and/or forecasting A track record of working cross-functionally and communicating effectively with both technical and non-technical partners Experience supporting one or more of the following: Product, Marketing, Finance, or internal Platform/Tooling teams While it’s not required, it’s an added plus if you also have: A self-starter attitude and the ability to thrive in ambiguous and fast-paced environments At Figma, one of our values is Grow as you go. We believe in hiring smart, curious people who are excited to learn and develop their skills. If you’re excited about this role but your past experience doesn’t align perfectly with the points outlined in the job description, we encourage you to apply anyways. You may be just the right candidate for this or other roles. Pay Transparency Disclosure If based in Figma’s San Francisco or New York hub offices, this role has the annual base salary range stated below. Job level and actual compensation will be decided based on factors including, but not limited to, individual qualifications objectively assessed during the interview process (including skills and prior relevant experience, potential impact, and scope of role), market demands, and specific work location. The listed range is a guideline, and the range for this role may be modified. For roles that are available to be filled remotely, the pay range is localized according to employee work location by a factor of between 80% and 100% of range. Please discuss your specific work location with your recruiter for more information. Figma offers equity to employees, as well a competitive package of additional benefits, including health, dental & vision, retirement with company contribution, parental leave & reproductive or family planning support, mental health & wellness benefits, generous PTO, company recharge days, a learning & development stipend, a work from home stipend, and cell phone reimbursement. Figma also offers sales incentive pay for most sales roles and an annual bonus plan for eligible non-sales roles. Figma’s compensation and benefits are subject to change and may be modified in the future. Annual Base Salary Range: $140,000 — $348,000 USD At Figma we celebrate and support our differences. We know employing a team rich in diverse thoughts, experiences, and opinions allows our employees, our product and our community to flourish. Figma is an equal opportunity workplace - we are dedicated to equal employment opportunities regardless of race, color, ancestry, religion, sex, national origin, sexual orientation, age, citizenship, marital status, disability, gender identity/expression, veteran status , or any other characteristic protected by law. We also consider qualified applicants regardless of criminal histories, consistent with legal requirements. We will work to ensure individuals with disabilities are provided reasonable accommodation to apply for a role, participate in the interview process, perform essential job functions, and receive other benefits and privileges of employment. If you require accommodation, please reach out to accommodations-ext@figma.com . These modifications enable an individual with a disability to have an equal opportunity not only to get a job, but successfully perform their job tasks to the same extent as people without disabilities. Examples of accommodations include but are not limited to: Holding interviews in an accessible location Enabling closed captioning on video conferencing Ensuring all written communication be compatible with screen readers Changing the mode or format of interviews To ensure the integrity of our hiring process and facilitate a more personal connection, we require all candidates keep their cameras on during video interviews. Additionally, if hired you will be required to attend in person onboarding. By applying for this job, the candidate acknowledges and agrees that any personal data contained in their application or supporting materials will be processed in accordance with Figma's Candidate Privacy Notice . | M3: 0 | N3: =I3+J3 -> 1 | O3: {=OR(B3=Hist!$A$1:$A$85)} -> TRUE
A4: {=SUM((B4=$B$2:$B$127)*1)} -> 1 | B4: greenhouse|figma|6013304004 | C4: greenhouse | D4: Figma | E4: figma | F4: 6013304004 | G4: Data Scientist, Finance | H4: San Francisco, CA • New York, NY • United States | I4: 1 | J4: 0 | K4: https://boards.greenhouse.io/figma/jobs/6013304004?gh_jid=6013304004 | L4: Figma is growing our team of passionate creatives and builders on a mission to make design accessible to all. Figma’s platform helps teams bring ideas to life—whether you're brainstorming, creating a prototype, translating designs into code, or iterating with AI. From idea to product, Figma empowers teams to streamline workflows, move faster, and work together in real time from anywhere in the world. If you're excited to shape the future of design and collaboration, join us! Figma is growing our Finance Data Science team at a pivotal moment in the company's evolution. As a public company, the accuracy, scalability, and sophistication of our financial data systems have never been more important. At the same time, Figma's business continues to evolve through new products, AI-powered offerings, acquisitions, and emerging revenue models. We're looking for a Finance Data Scientist to help build the data foundation that powers financial reporting, forecasting, strategic decision-making, and investor communications. In this role, you'll partner closely with Strategic Finance, Accounting, Investor Relations, Engineering, Product, and Data teams to ensure our financial metrics are accurate, actionable, and trusted across the business. This is a unique opportunity to work at the intersection of finance, analytics, data engineering, and business strategy—helping shape how Figma measures and communicates its performance as the company scales. The data and systems built by this team directly support executive decision-making, public company reporting, and Figma's long-term growth strategy. This is a full time role that can be held from one of our US hubs or remotely in the United States. What you'll do at Figma: Own and improve the data models that power Figma's financial reporting, including ARR, revenue, billings, collections, and other key business metrics Build scalable reporting systems, forecasts, and analytical frameworks that support Finance, Accounting, Investor Relations, and executive leadership Drive data accuracy and completeness across month-end, quarter-end, and year-end close processes alongside Strategic Finance and Accounting teams Collaborate with Engineering, Product, GTM Systems, and Financial Systems teams to ensure the completeness and accuracy of financial data Conduct deep-dive analyses that inform strategic decisions and uncover opportunities to improve business performance Define, measure, and operationalize key financial and operational metrics Design and implement durable data solutions that balance immediate stakeholder needs with long-term scalability Serve as a trusted thought partner to Finance leaders, helping guide reporting, forecasting, and decision-making across the business We'd love to hear from you if you have: 3+ years of experience in Data Science, Analytics, Finance, Financial Systems, Data Engineering, or a related field Advanced SQL skills and strong proficiency in Python or a similar programming language Experience supporting Finance, Accounting, Strategic Finance, FP&A, Investor Relations, or other finance-focused stakeholders Demonstrated ability to translate complex data into clear, actionable business insights for non-technical stakeholders Experience working independently and driving projects from ambiguity to execution While it's not required, it's an added plus if you also have: Experience with SaaS, subscription-based, usage-based, or consumption-based business models Knowledge of accounting concepts and revenue recognition principles (ASC 606) Experience with modern analytics and data engineering tools such as DBT, Snowflake, Git, Spark, Presto, or similar technologies Experience supporting IPO readiness, public company reporting, SOX controls, audits, or other major corporate milestones Background in Strategic Finance, FP&A, Accounting, Investment Banking, Consulting, or related fields At Figma, one of our values is Grow as you go. We believe in hiring smart, curious people who are excited to learn and develop their skills. If you’re excited about this role but your past experience doesn’t align perfectly with the points outlined in the job description, we encourage you to apply anyways. You may be just the right candidate for this or other roles. Pay Transparency Disclosure If based in Figma’s San Francisco or New York hub offices, this role has the annual base salary range stated below. Job level and actual compensation will be decided based on factors including, but not limited to, individual qualifications objectively assessed during the interview process (including skills and prior relevant experience, potential impact, and scope of role), market demands, and specific work location. The listed range is a guideline, and the range for this role may be modified. For roles that are available to be filled remotely, the pay range is localized according to employee work location by a factor of between 80% and 100% of range. Please discuss your specific work location with your recruiter for more information. Figma offers equity to employees, as well a competitive package of additional benefits, including health, dental & vision, retirement with company contribution, parental leave & reproductive or family planning support, mental health & wellness benefits, generous PTO, company recharge days, a learning & development stipend, a work from home stipend, and cell phone reimbursement. Figma also offers sales incentive pay for most sales roles and an annual bonus plan for eligible non-sales roles. Figma’s compensation and benefits are subject to change and may be modified in the future. Annual Base Salary Range: $140,000 — $348,000 USD At Figma we celebrate and support our differences. We know employing a team rich in diverse thoughts, experiences, and opinions allows our employees, our product and our community to flourish. Figma is an equal opportunity workplace - we are dedicated to equal employment opportunities regardless of race, color, ancestry, religion, sex, national origin, sexual orientation, age, citizenship, marital status, disability, gender identity/expression, veteran status , or any other characteristic protected by law. We also consider qualified applicants regardless of criminal histories, consistent with legal requirements. We will work to ensure individuals with disabilities are provided reasonable accommodation to apply for a role, participate in the interview process, perform essential job functions, and receive other benefits and privileges of employment. If you require accommodation, please reach out to accommodations-ext@figma.com . These modifications enable an individual with a disability to have an equal opportunity not only to get a job, but successfully perform their job tasks to the same extent as people without disabilities. Examples of accommodations include but are not limited to: Holding interviews in an accessible location Enabling closed captioning on video conferencing Ensuring all written communication be compatible with screen readers Changing the mode or format of interviews To ensure the integrity of our hiring process and facilitate a more personal connection, we require all candidates keep their cameras on during video interviews. Additionally, if hired you will be required to attend in person onboarding. By applying for this job, the candidate acknowledges and agrees that any personal data contained in their application or supporting materials will be processed in accordance with Figma's Candidate Privacy Notice . | M4: 0 | N4: =I4+J4 -> 1 | O4: {=OR(B4=Hist!$A$1:$A$85)} -> TRUE
A5: {=SUM((B5=$B$2:$B$127)*1)} -> 1 | B5: greenhouse|figma|6013303004 | C5: greenhouse | D5: Figma | E5: figma | F5: 6013303004 | G5: Data Scientist, Marketing | H5: San Francisco, CA • New York, NY • United States | I5: 1 | J5: 0 | K5: https://boards.greenhouse.io/figma/jobs/6013303004?gh_jid=6013303004 | L5: Figma is growing our team of passionate creatives and builders on a mission to make design accessible to all. Figma’s platform helps teams bring ideas to life—whether you're brainstorming, creating a prototype, translating designs into code, or iterating with AI. From idea to product, Figma empowers teams to streamline workflows, move faster, and work together in real time from anywhere in the world. If you're excited to shape the future of design and collaboration, join us! We're looking for a Marketing Data Scientist to join Figma's Data Science team and help drive how we measure, optimize, and scale our marketing investments across the customer journey. In this role, you'll work closely with Paid Marketing, Lifecycle Marketing, Demand Generation, and Growth teams to develop measurement frameworks, improve targeting and segmentation, evaluate marketing effectiveness, and uncover insights that drive business growth. This role sits at the intersection of analytics, experimentation, and strategy. You'll work with marketing leaders to answer some of Figma's most important growth questions, including how we acquire and engage customers efficiently, which marketing investments drive incremental business impact, and how we can improve the effectiveness of our marketing programs at scale. This is a unique opportunity to shape the future of marketing measurement at Figma. You'll help build best-in-class capabilities across attribution, incrementality, experimentation, forecasting, and marketing mix modeling, while partnering with stakeholders across Marketing, Finance, Product, and Research to influence high-impact decisions and accelerate growth. What you'll do at Figma: Develop and own end-to-end measurement frameworks and attribution models to evaluate the effectiveness of Figma's marketing investments across the full funnel, channels, and regions. Partner with stakeholders across Brand Marketing, Email, Lifecycle, Demand Gen and Research teams to define success metrics, uncover insights, and drive data-informed decision making. Develop and apply statistical and machine learning models to solve key marketing challenges, including audience targeting, creative effectiveness, customer engagement, and campaign performance measurement. Assess the incremental impact of marketing investments across channels to inform budget allocation and growth strategies. Build dashboards, reporting frameworks, and analytical tools that help stakeholders understand brand performance and business impact. Translate complex analyses into clear recommendations for marketing leaders and executive stakeholders. Drive foundational improvements in data quality, measurement infrastructure, and reporting capabilities across the marketing organization. Identify new opportunities to improve marketing effectiveness and influence strategic planning through data-driven insights. We'd love to hear from you if you have: 5+ years of experience in Data Science, Marketing Analytics, or a related analytical role, supporting Marketing teams and measuring large-scale investments. Strong foundation in statistics, experimentation, causal inference, and working with survey or qualitative research data. Advanced proficiency in SQL and experience using Python, R, or similar tools to conduct analysis and build scalable measurement solutions. Demonstrated ability to communicate complex analyses clearly to senior non-technical stakeholders, with a track record of influencing decisions in cross-functional environments. While it's not required, it's an added plus if you also have: Experience with marketing mix modeling (MMM), multi-touch attribution, or incrementality testing. Familiarity with data visualization tools such as Tableau, Looker, or similar. Pay Transparency Disclosure If based in Figma’s San Francisco or New York hub offices, this role has the annual base salary range stated below. Job level and actual compensation will be decided based on factors including, but not limited to, individual qualifications objectively assessed during the interview process (including skills and prior relevant experience, potential impact, and scope of role), market demands, and specific work location. The listed range is a guideline, and the range for this role may be modified. For roles that are available to be filled remotely, the pay range is localized according to employee work location by a factor of between 80% and 100% of range. Please discuss your specific work location with your recruiter for more information. Figma offers equity to employees, as well a competitive package of additional benefits, including health, dental & vision, retirement with company contribution, parental leave & reproductive or family planning support, mental health & wellness benefits, generous PTO, company recharge days, a learning & development stipend, a work from home stipend, and cell phone reimbursement. Figma also offers sales incentive pay for most sales roles and an annual bonus plan for eligible non-sales roles. Figma’s compensation and benefits are subject to change and may be modified in the future. Annual Base Salary Range: $140,000 — $348,000 USD At Figma we celebrate and support our differences. We know employing a team rich in diverse thoughts, experiences, and opinions allows our employees, our product and our community to flourish. Figma is an equal opportunity workplace - we are dedicated to equal employment opportunities regardless of race, color, ancestry, religion, sex, national origin, sexual orientation, age, citizenship, marital status, disability, gender identity/expression, veteran status , or any other characteristic protected by law. We also consider qualified applicants regardless of criminal histories, consistent with legal requirements. We will work to ensure individuals with disabilities are provided reasonable accommodation to apply for a role, participate in the interview process, perform essential job functions, and receive other benefits and privileges of employment. If you require accommodation, please reach out to accommodations-ext@figma.com . These modifications enable an individual with a disability to have an equal opportunity not only to get a job, but successfully perform their job tasks to the same extent as people without disabilities. Examples of accommodations include but are not limited to: Holding interviews in an accessible location Enabling closed captioning on video conferencing Ensuring all written communication be compatible with screen readers Changing the mode or format of interviews To ensure the integrity of our hiring process and facilitate a more personal connection, we require all candidates keep their cameras on during video interviews. Additionally, if hired you will be required to attend in person onboarding. By applying for this job, the candidate acknowledges and agrees that any personal data contained in their application or supporting materials will be processed in accordance with Figma's Candidate Privacy Notice . | M5: 0 | N5: =I5+J5 -> 1 | O5: {=OR(B5=Hist!$A$1:$A$85)} -> TRUE
A6: {=SUM((B6=$B$2:$B$127)*1)} -> 1 | B6: greenhouse|figma|5551532004 | C6: greenhouse | D6: Figma | E6: figma | F6: 5551532004 | G6: Software Engineer, Machine Learning | H6: San Francisco, CA • New York, NY • United States | I6: 1 | J6: 0 | K6: https://boards.greenhouse.io/figma/jobs/5551532004?gh_jid=5551532004 | L6: Figma is growing our team of passionate creatives and builders on a mission to make design accessible to all. Figma’s platform helps teams bring ideas to life—whether you're brainstorming, creating a prototype, translating designs into code, or iterating with AI. From idea to product, Figma empowers teams to streamline workflows, move faster, and work together in real time from anywhere in the world. If you're excited to shape the future of design and collaboration, join us! Figma is seeking a versatile and experienced Machine Learning / AI Engineer to join our growing AI team, working at the intersection of applied machine learning, infrastructure, and product innovation. Whether you’re building intelligent search systems, crafting scalable data pipelines, or enhancing AI-powered creativity tools, your work will drive user productivity, shape new product experiences, and advance the state of AI at Figma. You’ll collaborate closely with engineers, researchers, designers, and product managers across multiple teams to deliver high-quality ML-driven features and infrastructure. This is a high-impact, cross-functional role where you’ll shape both foundational systems and user-facing capabilities. This is a full time role that can be held from one of our US hubs or remotely in the United States. What you’ll do at Figma: Design, build, and productionize ML models for Search, Discovery, Ranking, Retrieval-Augmented Generation (RAG), and generative AI features. Build and maintain scalable data pipelines to collect high-quality training and evaluation datasets, including annotation systems and human-in-the-loop workflows. Collaborate with AI researchers to iterate on datasets, evaluation metrics, and model architectures to improve quality and relevance. Work with product engineers to define and deliver impactful AI features across Figma’s platform. Partner with infrastructure engineers to develop and optimize systems for training, inference, monitoring, and deployment. Explore new ideas at the edge of what’s technically possible and help shape the long-term AI vision at Figma. We’d love to hear from you If you have: 5+ years of industry experience in software engineering, with 3+ years focused on applied machine learning or AI. Strong experience with end-to-end ML model development, including training, evaluation, deployment, and monitoring. Proficiency in Python and familiarity with ML libraries like PyTorch, TensorFlow, Scikit-learn, Spark MLlib, or XGBoost. Experience designing and building scalable data and annotation pipelines, as well as evaluation systems for AI model quality. Experience mentoring or leading others and contributing to a culture of technical excellence and innovation. While not required, It’s an added plus if you also have: Familiarity with search relevance, ranking, NLP, or RAG systems. Experience with AI infrastructure and MLOps, including observability, CI/CD, and automation for ML workflows. Experience working on creative or design-focused ML applications. Knowledge of additional languages such as C++ or Go is a plus, but not required. A product mindset with the ability to tie technical work to user outcomes and business impact. Strong collaboration and communication skills, especially when working across functions (engineering, product, research). At Figma, one of our values is Grow as you go. We believe in hiring smart, curious people who are excited to learn and develop their skills. If you’re excited about this role but your past experience doesn’t align perfectly with the points outlined in the job description, we encourage you to apply anyways. You may be just the right candidate for this or other roles. Pay Transparency Disclosure If based in Figma’s San Francisco or New York hub offices, this role has the annual base salary range stated below. Job level and actual compensation will be decided based on factors including, but not limited to, individual qualifications objectively assessed during the interview process (including skills and prior relevant experience, potential impact, and scope of role), market demands, and specific work location. The listed range is a guideline, and the range for this role may be modified. For roles that are available to be filled remotely, the pay range is localized according to employee work location by a factor of between 80% and 100% of range. Please discuss your specific work location with your recruiter for more information. Figma offers equity to employees, as well a competitive package of additional benefits, including health, dental & vision, retirement with company contribution, parental leave & reproductive or family planning support, mental health & wellness benefits, generous PTO, company recharge days, a learning & development stipend, a work from home stipend, and cell phone reimbursement. Figma also offers sales incentive pay for most sales roles and an annual bonus plan for eligible non-sales roles. Figma’s compensation and benefits are subject to change and may be modified in the future. Annual Base Salary Range: $153,000 — $376,000 USD At Figma we celebrate and support our differences. We know employing a team rich in diverse thoughts, experiences, and opinions allows our employees, our product and our community to flourish. Figma is an equal opportunity workplace - we are dedicated to equal employment opportunities regardless of race, color, ancestry, religion, sex, national origin, sexual orientation, age, citizenship, marital status, disability, gender identity/expression, veteran status , or any other characteristic protected by law. We also consider qualified applicants regardless of criminal histories, consistent with legal requirements. We will work to ensure individuals with disabilities are provided reasonable accommodation to apply for a role, participate in the interview process, perform essential job functions, and receive other benefits and privileges of employment. If you require accommodation, please reach out to accommodations-ext@figma.com . These modifications enable an individual with a disability to have an equal opportunity not only to get a job, but successfully perform their job tasks to the same extent as people without disabilities. Examples of accommodations include but are not limited to: Holding interviews in an accessible location Enabling closed captioning on video conferencing Ensuring all written communication be compatible with screen readers Changing the mode or format of interviews To ensure the integrity of our hiring process and facilitate a more personal connection, we require all candidates keep their cameras on during video interviews. Additionally, if hired you will be required to attend in person onboarding. By applying for this job, the candidate acknowledges and agrees that any personal data contained in their application or supporting materials will be processed in accordance with Figma's Candidate Privacy Notice . | M6: 0 | N6: =I6+J6 -> 1 | O6: {=OR(B6=Hist!$A$1:$A$85)} -> TRUE
A7: {=SUM((B7=$B$2:$B$127)*1)} -> 1 | B7: ashby|notion|a1216dba-e175-4a3d-b712-401c9fbdcd92 | C7: ashby | D7: Notion | E7: notion | F7: a1216dba-e175-4a3d-b712-401c9fbdcd92 | G7: Data Engineer, People Analytics | H7: San Francisco, California | I7: 1 | J7: 0 | K7: https://jobs.ashbyhq.com/notion/a1216dba-e175-4a3d-b712-401c9fbdcd92 | L7: WHO WE ARE Notion is the collaborative AI workspace where teams and agents think together https://www.youtube.com/watch?v=vkpYpWfEK5s. We're building one place where your knowledge, projects, meetings, and AI tools live side by side, so work is faster, clearer, and less fragmented. Millions of individuals, small teams, and large companies run their work on Notion. Notinos (our employees) are customer zero in bringing this future of work to life. We care about craft, building things that last, and the belief that great work is still fundamentally human. Our goal isn’t to ship the next feature. Each and every team of Notinos is working to set the standard for how humans work together in the AI era. From building a business’s system of record to making and managing AI agents to automating away the busy work, we care deeply about giving our customers more time for their life’s work. ABOUT THE ROLE As Notion scales, there is a unique opportunity to build the data foundations for People Analytics that enable better decisions around hiring, performance, compensation, and org design - while maintaining strong privacy guarantees for sensitive employee data. In this role, you will design, build, and operate scalable data systems and pipelines that power People data. Your work will ensure that employee data is reliable, secure, and production-ready, enabling both analytics and AI-driven people workflows across the company. This role can be based in either San Francisco or New York City. We work from our offices on Mondays, Tuesdays and Thursdays (our Anchor Days) because we do our best thinking and building together in person. We’re looking for someone who’s excited to work alongside the team during those days. WHAT YOU'LL ACHIEVE - Partner closely with the Chief People Officer and People leadership team to translate strategic questions into clear metrics and data products that inform workforce planning, organization design, performance reviews, compensation discussions, and executive reporting - Define and build ETL/ELT pipelines and infrastructure to ingest and standardize data from HRIS and adjacent systems such as Workday, ATS, payroll, benefits, performance platforms, creating a reliable source of truth for headcount, org structure, hiring, attrition, and talent health - Design privacy-first data architecture, including access controls, PII handling, and governance standards - Implement data quality, testing, and observability systems to ensure sensitive employee data is accurate and trustworthy - Design privacy-aware data models, transformations, semantic layers, and quality checks so sensitive employee data is accurate, timely, well-documented, and governed appropriately with role-based access controls for decision-making and makes AI-powered people tools and automations reliable enough to ship to production - Partner with People Analytics to translate ambiguous requirements into scalable datasets, dashboards, and self-serve data products that give People leaders, People Partners, and managers visibility into workforce trends while reducing manual overhead. SKILLS YOU'LL NEED TO BRING - 6+ years of experience in analytics engineering, data engineering, people analytics, or a closely related role, with a track record of building trusted datasets and systems for business decision-making - Hands-on experience working with HRIS and adjacent People systems data (for example Workday, ATS (Ashby), payroll, benefits, performance, or engagement platforms) and know how to reconcile definitions across messy, evolving source systems - Proficiency in SQL and data modeling, and can build production-grade transformations, define durable metric logic, and write performant queries against large analytical datasets - Proficiency in Python (or similar OOP languages) for building data pipelines, automation, and infrastructure - Experience designing systems with data quality, testing, monitoring, and SLAs in mind - Experience with modern data tooling and cloud warehouses such as Snowflake, dbt, Airflow, Fivetran, or similar technologies, along with strong instincts around testing, monitoring, and data quality - Excellent judgment with sensitive and confidential data, and can implement infrastructure and tooling for data privacy, access controls, governance, and thoughtful interpretation of people metrics - Effectiveness in partnering directly with the CPO, People Partners, Finance, and business leaders to turn ambiguous questions into scoped solutions and clearly communicated insights - Ability to leverage AI and agent-based tools to accelerate development, while defining guardrails for safe, production-grade data workflows NICE TO HAVES - You have worked at a fast-growing start-up, a SaaS company or are eager to contribute in such an environment (being a current Notion user would be great!) Notion is committed to providing highly competitive cash compensation, equity, and benefits. The compensation offered for this role will be based on multiple factors such as location, the role’s scope and complexity, and the candidate’s experience and expertise, and may vary from the range provided below. For roles based in San Francisco, the estimated base salary range for this role is $213,000 to $250,000 By clicking “Submit Application”, I understand and agree that Notion and its affiliates and subsidiaries will collect and process my information in accordance with Notion’s Global Recruiting Privacy Policy https://notion.notion.site/Notion-Global-Recruiting-Privacy-Policy-fc3eb4e829354a26a2bb6fd5e289b550. https://dev.notion.so/a3ce416456924276a59de91bca740028?pvs=21#LI-Onsite #LI-Onsite A NOTE ON AI You don’t need deep AI expertise for every role, but we do expect every Notino to be intellectually curious, drawn to tinkering and discovery, and excited to use AI as a real collaborator in their work. For some roles, AI fluency is a core requirement — when that’s the case, we'll say so explicitly in the qualifications. People who thrive here don’t treat AI as a novelty. They use it to think better, and make their work easier for others to build on. EQUAL OPPORTUNITY & ACCOMMODATIONS We hire talented people from a wide range of backgrounds. If you’re excited about this role but don’t meet every bullet, we still encourage you to apply. Notion is an equal opportunity employer and does not discriminate on the basis of any legally protected characteristic. Consistent with applicable law, we will consider for employment qualified applicants with arrest and conviction records. Notion provides reasonable accommodations during the application process; if you need one, please let your recruiter know. Notion is proud to be an equal opportunity employer. We do not discriminate in hiring or any employment decision based on race, color, religion, national origin, age, sex (including pregnancy, childbirth, or related medical conditions), marital status, ancestry, physical or mental disability, genetic information, veteran status, gender identity or expression, sexual orientation, or other applicable legally protected characteristic. Notion considers qualified applicants with criminal histories, consistent with applicable federal, state and local law. Notion is also committed to providing reasonable accommodations for qualified individuals with disabilities and disabled veterans in our job application procedures. If you need assistance or an accommodation due to a disability, please let your recruiter know. | M7: 0 | N7: =I7+J7 -> 1 | O7: {=OR(B7=Hist!$A$1:$A$85)} -> TRUE
A8: {=SUM((B8=$B$2:$B$127)*1)} -> 1 | B8: ashby|notion|e4229ca4-8210-4282-98ed-2071478f72aa | C8: ashby | D8: Notion | E8: notion | F8: e4229ca4-8210-4282-98ed-2071478f72aa | G8: People Analytics & Operations (Rotational Program) | H8: San Francisco, California | I8: 1 | J8: 0 | K8: https://jobs.ashbyhq.com/notion/e4229ca4-8210-4282-98ed-2071478f72aa | L8: WHO WE ARE Notion is the collaborative AI workspace where teams and agents think together https://www.youtube.com/watch?v=vkpYpWfEK5s. We're building one place where your knowledge, projects, meetings, and AI tools live side by side, so work is faster, clearer, and less fragmented. Millions of individuals, small teams, and large companies run their work on Notion. Notinos (our employees) are customer zero in bringing this future of work to life. We care about craft, building things that last, and the belief that great work is still fundamentally human. Our goal isn’t to ship the next feature. Each and every team of Notinos is working to set the standard for how humans work together in the AI era. From building a business’s system of record to making and managing AI agents to automating away the busy work, we care deeply about giving our customers more time for their life’s work. ABOUT THE ROLE: You're joining Notion's People Analytics & Operations team as part of an 18-month rotational program -- the group that builds the insights engine powering every people decision Notion makes. We look for slope over intercept. We care less about where you trained and more about what you've built. If you've ever rebuilt a broken process because it was bothering you, used AI to do something you couldn't have done alone, or found yourself reading about labor economics for fun -- you're the person we're looking for. Over 18 months, you'll rotate across people operations, people analytics, and compensation/benefits. Every rotation is real work with real ownership. On the analytics side, you'll build dashboards that land in exec review, write SQL that powers headcount models, and prototype AI-assisted workflows that help our team move faster. On the operations side, you'll run the HR engine -- managing employee lifecycle transactions in Workday, owning onboarding and offboarding coordination end-to-end, triaging and resolving employee requests, and keeping our people data clean and audit-ready. You'll be paired with a senior operator who will push your craft and raise your bar. We want someone who's hungry, high-agency, and passionate about leveraging AI to build the future of work. Not "I've used ChatGPT" native -- "I use AI every day to move faster and build smarter" native. And you don't just use Notion; you build in it. At the end of 18 months, you'll declare a focus area and move into a permanent team within the People org -- whether that's People Analytics, People Operations, Total Rewards, or staying broad as a high-impact People generalist. We're intentionally building the next generation of the People team from within. WHAT YOU'LL ACHIEVE: - Build the insights engine: Write SQL that powers our headcount, attrition, and hiring funnel dashboards. Transform raw people data from Workday and Snowflake into crisp analyses that drive real decisions. For example, you might build a model that identifies where we're losing great candidates and propose a process fix. - Run the HR operations engine: You'll learn how the ops side of the house actually works by doing it. That means executing employee lifecycle transactions in Workday (new hires, transfers, terminations), coordinating onboarding and offboarding end-to-end, triaging and resolving employee requests, supporting compliance and audit readiness, and keeping headcount and requisition data clean. For example, you might own the full ops flow for an onboarding cohort and surface process gaps that shorten time-to-productivity. - Tell the story in data: Take a messy people question and produce a clean narrative: numbers to insights to recommended decision. You'll own the analytical arc end-to-end -- from pulling the data to presenting it to senior leadership. - Prototype AI-assisted workflows: Identify manual, repetitive work across HR operations and replace it with something smarter -- automated onboarding task routing, AI-assisted ticket triage, offboarding checklists that run themselves, compliance reminders that don't require a human to send. You'll have real latitude to experiment and ship things that outlive your rotation. - Build and own our Notion workspace: You'll be the People team's Notion expert. Pages, databases, dashboards, views -- you'll build operating systems the whole team relies on. From day one, you'll be the person others come to when they want to do something in Notion they didn't know was possible. SKILLS YOU'LL NEED TO BRING: - SQL is your native language: You don't reach for SQL when you have to; you reach for it when you want to think. You can write queries that join, filter, aggregate, and transform data. You debug the wrong answer and figure out exactly why it's wrong. - Quantitatively sharp: You think in numbers. You've studied business, economics, statistics, or mathematics and it showed up in your work. Analytical storytelling -- connecting numbers to insights to decisions -- is a skill you've already started building. - High agency, high urgency: You don't wait for perfect instructions. When something's broken, you fix it. When there's ambiguity, you make a call. We look for slope over intercept -- we care more about what you've built and how fast you learn than where you trained. - AI-fluent: You use AI tools every day as a real multiplier, not a novelty. You know when Claude drafts it faster, when a formula is cleaner, and when you need to write the code yourself. Come ready to show us how you've used AI to do something you couldn't have done alone. - Notion power user: You live in Notion. You know the difference between a filtered view and a linked database. You get a little excited when you find a cleaner way to structure something. From day one, you'll be one of the most fluent Notion users on the People team. NICE TO HAVES: - Some exposure to Python -- enough to know what a loop is and when to reach for one - Familiarity with Workday, Snowflake, or similar HRIS or data warehouse tools - Prior experience in a business operations, finance, or sales operations context (internships count) Notion is committed to providing highly competitive cash compensation, equity, and benefits. The compensation offered for this role will be based on multiple factors such as location, the role’s scope and complexity, and the candidate’s experience and expertise, and may vary from the range provided below. For roles based in San Francisco, the estimated base salary range for this role is $40.87 - $59.62 hourly. By clicking “Submit Application”, I understand and agree that Notion and its affiliates and subsidiaries will collect and process my information in accordance with Notion’s Global Recruiting Privacy Policy https://notion.notion.site/Notion-Global-Recruiting-Privacy-Policy-fc3eb4e829354a26a2bb6fd5e289b550. https://dev.notion.so/a3ce416456924276a59de91bca740028?pvs=21 #LI-Onsite A NOTE ON AI You don’t need deep AI expertise for every role, but we do expect every Notino to be intellectually curious, drawn to tinkering and discovery, and excited to use AI as a real collaborator in their work. For some roles, AI fluency is a core requirement — when that’s the case, we'll say so explicitly in the qualifications. People who thrive here don’t treat AI as a novelty. They use it to think better, and make their work easier for others to build on. EQUAL OPPORTUNITY & ACCOMMODATIONS We hire talented people from a wide range of backgrounds. If you’re excited about this role but don’t meet every bullet, we still encourage you to apply. Notion is an equal opportunity employer and does not discriminate on the basis of any legally protected characteristic. Consistent with applicable law, we will consider for employment qualified applicants with arrest and conviction records. Notion provides reasonable accommodations during the application process; if you need one, please let your recruiter know. Notion is proud to be an equal opportunity employer. We do not discriminate in hiring or any employment decision based on race, color, religion, national origin, age, sex (including pregnancy, childbirth, or related medical conditions), marital status, ancestry, physical or mental disability, genetic information, veteran status, gender identity or expression, sexual orientation, or other applicable legally protected characteristic. Notion considers qualified applicants with criminal histories, consistent with applicable federal, state and local law. Notion is also committed to providing reasonable accommodations for qualified individuals with disabilities and disabled veterans in our job application procedures. If you need assistance or an accommodation due to a disability, please let your recruiter know. | M8: 0 | N8: =I8+J8 -> 1 | O8: {=OR(B8=Hist!$A$1:$A$85)} -> TRUE
