Workbook

Sheet Comps
A1: Figma | B1: =TRIM(A1)=A1 -> TRUE
A2: Notion | B2: =TRIM(A2)=A2 -> TRUE
A3: Databricks | B3: =TRIM(A3)=A3 -> TRUE
A4: Klaviyo | B4: =TRIM(A4)=A4 -> TRUE
A5: Stripe | B5: =TRIM(A5)=A5 -> TRUE
A6: MongoDB | B6: =TRIM(A6)=A6 -> TRUE
A7: Snowflake | B7: =TRIM(A7)=A7 -> TRUE
A8: Coinbase | B8: =TRIM(A8)=A8 -> TRUE
A9: OpenAI | B9: =TRIM(A9)=A9 -> TRUE
A10: Relativity | B10: =TRIM(A10)=A10 -> TRUE
A11: Outreach | B11: =TRIM(A11)=A11 -> TRUE

Sheet Entries
A1: [ | B1: {=OR(A1=Comps!$A$1:$A$11)} -> FALSE
A2: { | B2: {=OR(A2=Comps!$A$1:$A$11)} -> FALSE
A3: "company": "Anthropic", | B3: {=OR(A3=Comps!$A$1:$A$11)} -> FALSE
A4: "platform": "greenhouse", | B4: {=OR(A4=Comps!$A$1:$A$11)} -> FALSE
A5: "slug": "anthropic" | B5: {=OR(A5=Comps!$A$1:$A$11)} -> FALSE
A6: }, | B6: {=OR(A6=Comps!$A$1:$A$11)} -> FALSE
A7: { | B7: {=OR(A7=Comps!$A$1:$A$11)} -> FALSE
A8: "company": "PolyAI", | B8: {=OR(A8=Comps!$A$1:$A$11)} -> FALSE
A9: "platform": "greenhouse", | B9: {=OR(A9=Comps!$A$1:$A$11)} -> FALSE
A10: "slug": "polyai" | B10: {=OR(A10=Comps!$A$1:$A$11)} -> FALSE
A11: }, | B11: {=OR(A11=Comps!$A$1:$A$11)} -> FALSE
A12: { | B12: {=OR(A12=Comps!$A$1:$A$11)} -> FALSE
... A427: ] | B427: {=OR(A427=Comps!$A$1:$A$11)} -> FALSE

Sheet all
A1: [
A2: {
A3: "company": "Figma",
A4: "platform": "greenhouse",
A5: "slug": "figma"
A6: },
A7: {
A8: "company": "Notion",
A9: "platform": "ashby",
A10: "slug": "notion"
A11: },
A12: {
... A482: ]

Sheet Comps-2
A1: Company
A2: Ada
A3: Airtable
A4: Aleph Alpha
A5: Amplemarket
A6: Anthropic
A7: Arize AI
A8: Attio
A9: Black Forest Labs
A10: Bland AI
A11: Boomi
A12: Causaly
... A97: Zapier

Sheet Sheet6
B1: [
B2: {
A3: Retool | B3: "company": "Retool", | C3: {=OR(A3='Comps-2'!$A$1:$A$97)} -> FALSE
A4: websearch | B4: "platform": "websearch", | C4: {=OR(A4='Comps-2'!$A$1:$A$97)} -> FALSE
A5: retool | B5: "slug": "retool" | C5: {=OR(A5='Comps-2'!$A$1:$A$97)} -> FALSE
B6: }, | C6: {=OR(A6='Comps-2'!$A$1:$A$97)} -> FALSE
B7: { | C7: {=OR(A7='Comps-2'!$A$1:$A$97)} -> FALSE
A8: LivePerson | B8: "company": "LivePerson", | C8: {=OR(A8='Comps-2'!$A$1:$A$97)} -> FALSE
A9: websearch | B9: "platform": "websearch", | C9: {=OR(A9='Comps-2'!$A$1:$A$97)} -> FALSE
A10: liveperson | B10: "slug": "liveperson" | C10: {=OR(A10='Comps-2'!$A$1:$A$97)} -> FALSE
B11: }, | C11: {=OR(A11='Comps-2'!$A$1:$A$97)} -> FALSE
B12: { | C12: {=OR(A12='Comps-2'!$A$1:$A$97)} -> FALSE
A13: Talkdesk | B13: "company": "Talkdesk", | C13: {=OR(A13='Comps-2'!$A$1:$A$97)} -> FALSE
A14: websearch | B14: "platform": "websearch", | C14: {=OR(A14='Comps-2'!$A$1:$A$97)} -> FALSE
A15: talkdesk | B15: "slug": "talkdesk" | C15: {=OR(A15='Comps-2'!$A$1:$A$97)} -> FALSE
B16: }, | C16: {=OR(A16='Comps-2'!$A$1:$A$97)} -> FALSE
B17: { | C17: {=OR(A17='Comps-2'!$A$1:$A$97)} -> FALSE
A18: Twilio | B18: "company": "Twilio", | C18: {=OR(A18='Comps-2'!$A$1:$A$97)} -> FALSE
A19: websearch | B19: "platform": "websearch", | C19: {=OR(A19='Comps-2'!$A$1:$A$97)} -> FALSE
A20: twilio | B20: "slug": "twilio" | C20: {=OR(A20='Comps-2'!$A$1:$A$97)} -> FALSE
B21: }, | C21: {=OR(A21='Comps-2'!$A$1:$A$97)} -> FALSE
B22: { | C22: {=OR(A22='Comps-2'!$A$1:$A$97)} -> FALSE
A23: Dialpad | B23: "company": "Dialpad", | C23: {=OR(A23='Comps-2'!$A$1:$A$97)} -> FALSE
A24: websearch | B24: "platform": "websearch", | C24: {=OR(A24='Comps-2'!$A$1:$A$97)} -> FALSE
A25: dialpad | B25: "slug": "dialpad" | C25: {=OR(A25='Comps-2'!$A$1:$A$97)} -> FALSE
B26: }, | C26: {=OR(A26='Comps-2'!$A$1:$A$97)} -> FALSE
B27: { | C27: {=OR(A27='Comps-2'!$A$1:$A$97)} -> FALSE
A28: Gong | B28: "company": "Gong", | C28: {=OR(A28='Comps-2'!$A$1:$A$97)} -> FALSE
A29: websearch | B29: "platform": "websearch", | C29: {=OR(A29='Comps-2'!$A$1:$A$97)} -> FALSE
A30: gong | B30: "slug": "gong" | C30: {=OR(A30='Comps-2'!$A$1:$A$97)} -> FALSE
B31: }, | C31: {=OR(A31='Comps-2'!$A$1:$A$97)} -> FALSE
B32: { | C32: {=OR(A32='Comps-2'!$A$1:$A$97)} -> FALSE
A33: Genesys | B33: "company": "Genesys", | C33: {=OR(A33='Comps-2'!$A$1:$A$97)} -> FALSE
A34: websearch | B34: "platform": "websearch", | C34: {=OR(A34='Comps-2'!$A$1:$A$97)} -> FALSE
A35: genesys | B35: "slug": "genesys" | C35: {=OR(A35='Comps-2'!$A$1:$A$97)} -> FALSE
B36: }, | C36: {=OR(A36='Comps-2'!$A$1:$A$97)} -> FALSE
B37: { | C37: {=OR(A37='Comps-2'!$A$1:$A$97)} -> FALSE
A38: Salesforce | B38: "company": "Salesforce", | C38: {=OR(A38='Comps-2'!$A$1:$A$97)} -> FALSE
A39: websearch | B39: "platform": "websearch", | C39: {=OR(A39='Comps-2'!$A$1:$A$97)} -> FALSE
A40: salesforce | B40: "slug": "salesforce" | C40: {=OR(A40='Comps-2'!$A$1:$A$97)} -> FALSE
...
